Workbook

Sheet Initial tests
G1: Head mode | N1: 100 | O1: kv | Q1: hVL | R1: 8.5 mmAl
G2: test 2 | K2: Blade pos | L2: x1 | M2: 14 | N2: 15 | O2: mA
A3: couch (cm) | B3: kv | C3: Gy | D3: uGy/s | G3: couch (cm) | H3: uGy/s | L3: x2 | M3: 14 | N3: 20 | O3: ms
A4: 0 | D4: 201 | G4: 0 | L4: y1 | M4: 10.7
A5: -5 | D5: 199 | G5: 0.5 | L5: y2 | M5: 10.7
A6: -10 | D6: 59.5 | G6: 1
A7: -15 | D7: 0 | G7: 1.5
G8: 2
G9: 2.5
G10: 3
G11: 3.5
G12: 4
G13: 4.5
G14: 5
G15: 5.5
G16: 6
G17: 6.5
G18: 7
G19: 7.5
... G34: 15
F36: 0 | G36: 0 | H36: 167 | J36: 165
F37: -0.5 | G37: 999.5 | H37: 165
F38: -1 | G38: 999 | H38: 164
F39: -1.5 | G39: 998.5 | H39: 162
F40: -2 | G40: 998 | H40: 156
F41: -2.5 | G41: 997.5 | H41: 151
F42: -3 | G42: 997 | H42: 145
F43: -3.5 | G43: 996.5 | H43: 136
F44: -4 | G44: 996 | H44: 133
F45: -4.5 | G45: 995.5 | H45: 111
F46: -5 | G46: 995 | H46: 105
F47: -5.5 | G47: 994.5 | H47: 94
F48: -6 | G48: 994 | H48: 83 | J48: 72.8
F49: -6.5 | G49: 993.5 | H49: 72 | J49: 60.4
F50: -7 | G50: 993 | H50: 59 | J50: 46.6
F51: -7.5 | G51: 992.5 | H51: 44 | J51: 33
F52: -8 | G52: 992 | I52: rf low? | J52: 28.5
F53: -8.5 | G53: 991.5 | J53: 26
F54: -9 | G54: 991 | J54: 24.5
F55: -9.5 | G55: 990.5 | J55: 24.5
...

Sheet Head
A1: Head | E1: x1 | F1: 14
B2: kvp | C2: 100 | E2: x2 | F2: 14
B3: mA | C3: 15 | E3: y1 | F3: 10.7
B4: ms | C4: 20 | E4: y2 | F4: 10.7
B5: frames/s | C5: 15
B6: Fan type | C6: Full
B7: Arc type | C7: Half
A9: kV | B9: 100.38 | C9: kV
A10: HVL | B10: 6.887 | C10: mm Al | K10: We need to convert the dose rate uGy/s ("New tests August" tab) to a mGy per projection
A11: Total filt | B11: 10.829 | C11: mmAl TF | K11: use the total frames per second to get the time for one frame
A12: Dose | B12: 1.392 | C12: mGy | K12: =1/B14 -> 0.067801667 | L12: s/frame
A13: Dose rate | B13: 0.171 | C13: mGy/s
A14: frame/s | B14: 14.7489 | C14: frame/s | K14: now we can use this to scale the values in New tests August

Sheet Pelvis
A1: Pelvis | F1: x1 | G1: 24.7 | H1: cm | J1: rf high
B2: kvp | C2: 125 | F2: x2 | G2: 3.3
B3: mA | C3: 60 | F3: y1 | G3: 10.7
B4: ms | C4: 20 | F4: y2 | G4: 10.7
B5: frames/s | C5: 15
B6: Fan type | C6: Half
B7: Arc type | C7: Full
A9: kV | B9: 129.04 | C9: kV | I9: We need to convert the dose rate uGy/s ("New tests August" tab) to a mGy per projection
A10: HVL | B10: 8.371 | C10: mm Al | I10: use the total frames per second to get the time for one frame
A11: Total filt | B11: - | C11: mmAl TF | I11: =1/B14 -> 0.067762614 | J11: s/frame
A12: Dose | B12: 9.28 | C12: mGy
A13: Dose rate | B13: 1.11 | C13: mGy/s | I13: now we can use this to scale the values in New tests August
A14: frame/s | B14: 14.7574 | C14: frame/s
I15: Centre of beam
I16: =(G1+G2)/2 -> 14 | J16: cm

Sheet Pelvis large
A1: Pelvis large | F1: x1 | G1: 24.7 | H1: cm | J1: rf high
B2: kvp | C2: 140 | F2: x2 | G2: 3.3
B3: mA | C3: 75 | F3: y1 | G3: 10.7
B4: ms | C4: 25 | F4: y2 | G4: 10.7
B5: frames/s | C5: 5
B6: Fan type | C6: Half
B7: Arc type | C7: Full
A9: kV | B9: 143.29 | C9: kV
A10: HVL | B10: 8.942 | C10: mm Al
A11: Total filt | B11: - | C11: mmAl TF
A12: Dose | B12: 6.008 | C12: mGy
A13: Dose rate | B13: 0.75 | C13: mGy/s
A14: frame/s | B14: 4.96689 | C14: frame/s

Sheet Breast
A1: Breast 360 | B1: half arc | C1: full fan | E1: Breast 200 | F1: half arc | G1: full fan | I1: x1 | J1: 14
B2: kvp | C2: 125 | F2: kvp | G2: 125 | I2: x2 | J2: 14
B3: mA | C3: 10 | F3: mA | G3: 10 | I3: y1 | J3: 10.7
B4: ms | C4: 10 | F4: ms | G4: 10 | I4: y2 | J4: 10.7
B5: frames/s | C5: 7 | F5: frames/s | G5: 7
B6: Fan type | C6: Full | F6: Fan type | G6: Full
B7: Arc type | C7: Half | F7: Arc type | G7: Half
A9: kV | B9: 122.89 | C9: kV | E9: kV | F9: 121.1 | G9: kV
A10: HVL | B10: 7.849 | C10: mm Al | E10: HVL | F10: 7.857 | G10: mm Al
A11: Total filt | B11: 9.88308 | C11: mmAl TF | E11: Total filt | F11: 10.8568 | G11: mmAl TF
A12: Dose | B12: 0.689 | C12: mGy | E12: Dose | F12: 0.556 | G12: mGy
A13: Dose rate | B13: 0.066 | C13: mGy/s | E13: Dose rate | F13: 0.006 | G13: mGy/s
A14: frame/s | B14: 7 | C14: frame/s | E14: frame/s | F14: - | G14: frame/s
A16: IGNORING THESE NUMBERS, BREAST 360 IS HALF FAN FULL ARC
B20: We need to convert the dose rate uGy/s ("New tests August" tab) to a mGy per projection
B21: use the total frames per second to get the time for one frame
B22: =1/B14 -> 0.14285714 | C22: s/frame
B24: now we can use this to scale the values in New tests August

Sheet Thorax
A1: Thorax | F1: x1 | G1: 24.7 | H1: cm
B2: kvp | C2: 125 | F2: x2 | G2: 3.3
B3: mA | C3: 15 | F3: y1 | G3: 10.7
B4: ms | C4: 20 | F4: y2 | G4: 10.7
B5: frames/s | C5: 15
B6: Fan type | C6: Half
B7: Arc type | C7: Full
A9: kV | B9: 123.96 | C9: kV
A10: HVL | B10: 7.953 | C10: mm Al | K10: We need to convert the dose rate uGy/s ("New tests August" tab) to a mGy per projection
A11: Total filt | B11: - | C11: mmAl TF | K11: use the total frames per second to get the time for one frame
A12: Dose | B12: 3.839 | C12: mGy | K12: =1/B14 -> 0.067724065
A13: Dose rate | B13: 0.321 | C13: mGy/s
A14: frame/s | B14: 14.7658 | C14: frame/s | K14: now we can use this to scale the values in New tests August

Sheet Image gently
A1: Image gently | E1: x1 | F1: 14 | H1: rf low
B2: kvp | C2: 80 | E2: x2 | F2: 14
B3: mA | C3: 20 | E3: y1 | F3: 10.7
B4: ms | C4: 10 | E4: y2 | F4: 10.7
B5: frames/s | C5: 15
B6: Fan type | C6: Full
B7: Arc type | C7: Half
A9: kV | B9: 79.81 | C9: kV
A10: HVL | B10: 5.737 | C10: mm Al
A11: Total filt | B11: 10.9072 | C11: mmAl TF
A12: Dose | B12: 0.631 | C12: mGy
A13: Dose rate | B13: 0.058 | C13: mGy/s
A14: frame/s | B14: 14.7813 | C14: frame/s

Sheet Collated data
A2: Head | B2: Mode | C2: RF high | E2: Pelvis | F2: Mode | G2: RF high | I2: Pelvis large | J2: Mode | K2: RF high | M2: Breast 360 | N2: Mode | O2: RF high | Q2: Breast 200 | R2: Mode | S2: RF high | U2: Thorax | V2: Mode | W2: RF high | Y2: Image gently | Z2: Mode | AA2: RF low
B3: kvp | C3: 100 | F3: kvp | G3: 125 | J3: kvp | K3: 140 | N3: kvp | O3: 125 | R3: kvp | S3: 125 | V3: kvp | W3: 125 | Z3: kvp | AA3: 80
B4: mA | C4: 15 | F4: mA | G4: 60 | J4: mA | K4: 75 | N4: mA | O4: 10 | R4: mA | S4: 10 | V4: mA | W4: 15 | Z4: mA | AA4: 20
B5: ms | C5: 20 | F5: ms | G5: 20 | J5: ms | K5: 25 | N5: ms | O5: 10 | R5: ms | S5: 10 | V5: ms | W5: 20 | Z5: ms | AA5: 10
B6: frames/s | C6: 15 | F6: frames/s | G6: 15 | J6: frames/s | K6: 5 | N6: frames/s | O6: 7 | R6: frames/s | S6: 7 | V6: frames/s | W6: 15 | Z6: frames/s | AA6: 15
B7: Fan type | C7: Full | F7: Fan type | G7: Half | J7: Fan type | K7: Half | N7: Fan type | O7: Full | R7: Fan type | S7: Full | V7: Fan type | W7: Half | Z7: Fan type | AA7: Full
B8: Arc type | C8: Half | F8: Arc type | G8: Full | J8: Arc type | K8: Full | N8: Arc type | O8: Half | R8: Arc type | S8: Half | V8: Arc type | W8: Full | Z8: Arc type | AA8: Half
A10: kV | B10: 100.38 | C10: kV | E10: kV | F10: 129.04 | G10: kV | I10: kV | J10: 143.29 | K10: kV | M10: kV | N10: 122.89 | O10: kV | Q10: kV | R10: 121.1 | S10: kV | U10: kV | V10: 123.96 | W10: kV | Y10: kV | Z10: 79.81 | AA10: kV
A11: HVL | B11: 6.887 | C11: mm Al | E11: HVL | F11: 8.371 | G11: mm Al | I11: HVL | J11: 8.942 | K11: mm Al | M11: HVL | N11: 7.849 | O11: mm Al | Q11: HVL | R11: 7.857 | S11: mm Al | U11: HVL | V11: 7.953 | W11: mm Al | Y11: HVL | Z11: 5.737 | AA11: mm Al
A12: Total filt | B12: 10.829 | C12: mmAl TF | E12: Total filt | F12: - | G12: mmAl TF | I12: Total filt | J12: - | K12: mmAl TF | M12: Total filt | N12: 9.88308 | O12: mmAl TF | Q12: Total filt | R12: 10.8568 | S12: mmAl TF | U12: Total filt | V12: - | W12: mmAl TF | Y12: Total filt | Z12: 10.9072 | AA12: mmAl TF
A13: Dose | B13: 1.392 | C13: mGy | E13: Dose | F13: 9.28 | G13: mGy | I13: Dose | J13: 6.008 | K13: mGy | M13: Dose | N13: 0.689 | O13: mGy | Q13: Dose | R13: 0.556 | S13: mGy | U13: Dose | V13: 3.839 | W13: mGy | Y13: Dose | Z13: 0.631 | AA13: mGy
A14: Dose rate | B14: 0.171 | C14: mGy/s | E14: Dose rate | F14: 1.11 | G14: mGy/s | I14: Dose rate | J14: 0.75 | K14: mGy/s | M14: Dose rate | N14: 0.066 | O14: mGy/s | Q14: Dose rate | R14: 0.006 | S14: mGy/s | U14: Dose rate | V14: 0.321 | W14: mGy/s | Y14: Dose rate | Z14: 0.058 | AA14: mGy/s
A15: frame/s | B15: 14.7489 | C15: frame/s | E15: frame/s | F15: 14.7574 | G15: frame/s | I15: frame/s | J15: 4.96689 | K15: frame/s | M15: frame/s | N15: - | O15: frame/s | Q15: frame/s | R15: - | S15: frame/s | U15: frame/s | V15: 14.7658 | W15: frame/s | Y15: frame/s | Z15: 14.7813 | AA15: frame/s
A17: Blades | E17: Blades | I17: Blades | M17: Blades | Q17: Blades | U17: Blades | Y17: Blades
A18: x1 | B18: 14 | C18: cm | E18: x1 | F18: 24.7 | G18: cm | I18: x1 | J18: 24.7 | K18: cm | M18: x1 | N18: 14 | O18: cm | Q18: x1 | R18: 14 | S18: cm | U18: x1 | V18: 24.7 | W18: cm | Y18: x1 | Z18: 14 | AA18: cm
A19: x2 | B19: 14 | E19: x2 | F19: 3.3 | I19: x2 | J19: 3.3 | M19: x2 | N19: 14 | Q19: x2 | R19: 14 | U19: x2 | V19: 3.3 | Y19: x2 | Z19: 14
A20: y1 | B20: 10.7 | E20: y1 | F20: 10.7 | I20: y1 | J20: 10.7 | M20: y1 | N20: 10.7 | Q20: y1 | R20: 10.7 | U20: y1 | V20: 10.7 | Y20: y1 | Z20: 10.7
A21: y2 | B21: 10.7 | E21: y2 | F21: 10.7 | I21: y2 | J21: 10.7 | M21: y2 | N21: 10.7 | Q21: y2 | R21: 10.7 | U21: y2 | V21: 10.7 | Y21: y2 | Z21: 10.7

Sheet New tests August
C2: Head | D2: Mode | E2: RF high | P2: Pelvis | Q2: Mode | R2: RF high | U2: Breast 360 | V2: Mode | W2: RF high | AA2: Pelvis large | AB2: Mode | AC2: RF high | AF2: Breast 200 | AG2: Mode | AH2: RF high | AK2: Thorax | AL2: Mode | AM2: RF high | AP2: Image gently | AQ2: Mode | AR2: RF low
D3: kvp | E3: 100 | Q3: kvp | R3: 125 | V3: kvp | W3: 125 | AB3: kvp | AC3: 140 | AG3: kvp | AH3: 125 | AL3: kvp | AM3: 125 | AQ3: kvp | AR3: 80
D4: mA | E4: 15 | Q4: mA | R4: 60 | V4: mA | W4: 10 | AB4: mA | AC4: 75 | AG4: mA | AH4: 10 | AL4: mA | AM4: 15 | AQ4: mA | AR4: 20
D5: ms | E5: 20 | Q5: ms | R5: 20 | V5: ms | W5: 10 | AB5: ms | AC5: 25 | AG5: ms | AH5: 10 | AL5: ms | AM5: 20 | AQ5: ms | AR5: 10
D6: frames/s | E6: 15 | Q6: frames/s | R6: 15 | V6: frames/s | W6: 7 | AB6: frames/s | AC6: 5 | AG6: frames/s | AH6: 7 | AL6: frames/s | AM6: 15 | AQ6: frames/s | AR6: 15
D7: Fan type | E7: Full | Q7: Fan type | R7: Half | V7: Fan type | W7: Full | AB7: Fan type | AC7: Half | AG7: Fan type | AH7: Full | AL7: Fan type | AM7: Half | AQ7: Fan type | AR7: Full | AY7: Outcomes of PCXMC
D8: Arc type | E8: Half | Q8: Arc type | R8: Full | V8: Arc type | W8: Half | AB8: Arc type | AC8: Full | AG8: Arc type | AH8: Half | AL8: Arc type | AM8: Full | AQ8: Arc type | AR8: Half
U9: THIS IS HALF FAN | AY9: ICRP103 | AZ9: effectove dose (mSv)
C10: INPLANE | I10: CROSSPLANE | U10: THIS DATA INCORRECT | AY10: protocol | AZ10: male 180cm 88kg
C11: Couch (cm) | D11: Dose rate uGy/s | E11: Total Filtration | I11: Couch (cm) | J11: Dose rate uGy/s | K11: Air kerma per projection | M11: Total Filtration | P11: Couch (cm) | Q11: Dose rate uGy/s | R11: HVL (TF not working) | U11: Couch (cm) | V11: Dose rate uGy/s | W11: HVL Al | X11: Total Filtration | AA11: Couch (cm) | AB11: Dose rate uGy/s | AC11: Total Filtration | AF11: Couch (cm) | AG11: Dose rate uGy/s | AH11: Total Filtration | AK11: Couch (cm) | AL11: Dose rate uGy/s | AM11: Total Filtration | AP11: Couch (cm) | AQ11: Dose rate uGy/s | AR11: Total Filtration | AY11: head | AZ11: 0.39
E12: HVL in Aarons work?? | K12: mGy/frame | M12: mmAl | Q12: B WALL | V12: B WALL | AB12: B WALL | AY12: Pelvis | AZ12: 4.85
B13: =B$45+C13 -> 99.6 | C13: 15 | D13: SUP | H13: =H$45+I13 -> 15.06 | I13: 15 | J13: B WALL | O13: =O$45+P13 -> 15.06 | P13: 15 | T13: =T$45+U13 -> 15.06 | U13: 15 | Z13: =Z$45+AA13 -> 15.06 | AA13: 15 | AF13: 15 | AK13: 15 | AP13: 15 | AY13: Breast360 | AZ13: 6.4
B14: =B$45+C14 -> 99.1 | C14: 14.5 | H14: =H$45+I14 -> 14.56 | I14: 14.5 | O14: =O$45+P14 -> 14.56 | P14: 14.5 | T14: =T$45+U14 -> 14.56 | U14: 14.5 | Z14: =Z$45+AA14 -> 14.56 | AA14: 14.5 | AF14: 14.5 | AK14: 14.5 | AP14: 14.5 | AY14: H&N/Shoulders | AZ14: 0.39
B15: =B$45+C15 -> 98.6 | C15: 14 | H15: =H$45+I15 -> 14.06 | I15: 14 | O15: =O$45+P15 -> 14.06 | P15: 14 | T15: =T$45+U15 -> 14.06 | U15: 14 | Z15: =Z$45+AA15 -> 14.06 | AA15: 14 | AF15: 14 | AK15: 14 | AP15: 14 | AY15: Thorax | AZ15: 2.86
B16: =B$45+C16 -> 98.1 | C16: 13.5 | H16: =H$45+I16 -> 13.56 | I16: 13.5 | O16: =O$45+P16 -> 13.56 | P16: 13.5 | T16: =T$45+U16 -> 13.56 | U16: 13.5 | Z16: =Z$45+AA16 -> 13.56 | AA16: 13.5 | AF16: 13.5 | AK16: 13.5 | AP16: 13.5
B17: =B$45+C17 -> 97.6 | C17: 13 | H17: =H$45+I17 -> 13.06 | I17: 13 | O17: =O$45+P17 -> 13.06 | P17: 13 | T17: =T$45+U17 -> 13.06 | U17: 13 | Z17: =Z$45+AA17 -> 13.06 | AA17: 13 | AF17: 13 | AK17: 13 | AP17: 13
B18: =B$45+C18 -> 97.1 | C18: 12.5 | H18: =H$45+I18 -> 12.56 | I18: 12.5 | O18: =O$45+P18 -> 12.56 | P18: 12.5 | T18: =T$45+U18 -> 12.56 | U18: 12.5 | Z18: =Z$45+AA18 -> 12.56 | AA18: 12.5 | AF18: 12.5 | AK18: 12.5 | AP18: 12.5
B19: =B$45+C19 -> 96.6 | C19: 12 | H19: =H$45+I19 -> 12.06 | I19: 12 | O19: =O$45+P19 -> 12.06 | P19: 12 | T19: =T$45+U19 -> 12.06 | U19: 12 | Z19: =Z$45+AA19 -> 12.06 | AA19: 12 | AF19: 12 | AK19: 12 | AP19: 12
B20: =B$45+C20 -> 96.1 | C20: 11.5 | H20: =H$45+I20 -> 11.56 | I20: 11.5 | O20: =O$45+P20 -> 11.56 | P20: 11.5 | T20: =T$45+U20 -> 11.56 | U20: 11.5 | Z20: =Z$45+AA20 -> 11.56 | AA20: 11.5 | AF20: 11.5 | AK20: 11.5 | AP20: 11.5
B21: =B$45+C21 -> 95.6 | C21: 11 | H21: =H$45+I21 -> 11.06 | I21: 11 | J21: colide with gantry head can't go further | O21: =O$45+P21 -> 11.06 | P21: 11 | T21: =T$45+U21 -> 11.06 | U21: 11 | Z21: =Z$45+AA21 -> 11.06 | AA21: 11 | AF21: 11 | AK21: 11 | AP21: 11
B22: =B$45+C22 -> 95.1 | C22: 10.5 | H22: =H$45+I22 -> 10.56 | I22: 10.5 | O22: =O$45+P22 -> 10.56 | P22: 10.5 | T22: =T$45+U22 -> 10.56 | U22: 10.5 | V22: 186 | W22: 10.78 | Z22: =Z$45+AA22 -> 10.56 | AA22: 10.5 | AB22: 1687 | AC22: 8.477 | AF22: 10.5 | AK22: 10.5 | AP22: 10.5
B23: =B$45+C23 -> 94.6 | C23: 10 | D23: too low for rdg | H23: =H$45+I23 -> 10.06 | I23: 10 | J23: 67.61 | K23: =J23*Head!$K$12/1000 -> 0.0045840707 | M23: 30.54 | O23: =O$45+P23 -> 10.06 | P23: 10 | Q23: 1008 | R23: 7.891 | T23: =T$45+U23 -> 10.06 | U23: 10 | V23: 196.3 | W23: 10.67 | Z23: =Z$45+AA23 -> 10.06 | AA23: 10 | AB23: 1695 | AC23: 8.551 | AF23: 10 | AK23: 10 | AP23: 10
B24: =B$45+C24 -> 94.1 | C24: 9.5 | D24: 251.7 | H24: =H$45+I24 -> 9.56 | I24: 9.5 | O24: =O$45+P24 -> 9.56 | P24: 9.5 | T24: =T$45+U24 -> 9.56 | U24: 9.5 | Z24: =Z$45+AA24 -> 9.56 | AA24: 9.5 | AF24: 9.5 | AK24: 9.5 | AP24: 9.5
B25: =B$45+C25 -> 93.6 | C25: 9 | D25: 202.8 | E25: 9 | H25: =H$45+I25 -> 9.06 | I25: 9 | J25: 79.31 | K25: =J25*Head!$K$12/1000 -> 0.0053773502 | M25: 22.48 | O25: =O$45+P25 -> 9.06 | P25: 9 | T25: =T$45+U25 -> 9.06 | U25: 9 | V25: 221.6 | W25: 10.681 | Z25: =Z$45+AA25 -> 9.06 | AA25: 9 | AF25: 9 | AK25: 9 | AP25: 9
B26: =B$45+C26 -> 93.35 | C26: 8.75 | D26: 367.3 | H26: =H$45+I26 -> 8.81 | I26: 8.75 | O26: =O$45+P26 -> 0.06 | T26: =T$45+U26 -> 0.06 | Z26: =Z$45+AA26 -> 0.06
A27: =A$45+C27 -> #VALUE! | B27: =B$45+C27 -> 93.1 | C27: 8.5 | D27: 418 | E27: 17.25 | H27: =H$45+I27 -> 8.56 | I27: 8.5 | J27: 93.62 | K27: =J27*Head!$K$12/1000 -> 0.006347592 | M27: 19.6 | O27: =O$45+P27 -> 8.56 | P27: 8.5 | T27: =T$45+U27 -> 8.56 | U27: 8.5 | Z27: =Z$45+AA27 -> 8.56 | AA27: 8.5 | AF27: 8.5 | AK27: 8.5 | AP27: 8.5
B28: =B$45+C28 -> 92.85 | C28: 8.25 | D28: 434 | E28: 12.28 | H28: =H$45+I28 -> 8.31 | I28: 8.25 | O28: =O$45+P28 -> 0.06 | T28: =T$45+U28 -> 0.06 | Z28: =Z$45+AA28 -> 0.06
B29: =B$45+C29 -> 92.6 | C29: 8 | D29: 457.9 | E29: 9.257 | H29: =H$45+I29 -> 8.06 | I29: 8 | J29: 124 | K29: =J29*Head!$K$12/1000 -> 0.0084074067 | M29: 25.85 | O29: =O$45+P29 -> 8.06 | P29: 8 | Q29: 1007 | R29: 8.17 | T29: =T$45+U29 -> 8.06 | U29: 8 | V29: 329.4 | W29: 10.101 | Z29: =Z$45+AA29 -> 8.06 | AA29: 8 | AB29: 1704 | AC29: 8.592 | AF29: 8 | AK29: 8 | AP29: 8
B30: =B$45+C30 -> 92.1 | C30: 7.5 | H30: =H$45+I30 -> 7.56 | I30: 7.5 | O30: =O$45+P30 -> 7.56 | P30: 7.5 | T30: =T$45+U30 -> 7.56 | U30: 7.5 | Z30: =Z$45+AA30 -> 7.56 | AA30: 7.5 | AF30: 7.5 | AK30: 7.5 | AP30: 7.5
B31: =B$45+C31 -> 91.6 | C31: 7 | D31: 458.3 | E31: 10.09 | H31: =H$45+I31 -> 7.06 | I31: 7 | J31: 200.7 | K31: =J31*Head!$K$12/1000 -> 0.013607794 | M31: 16.11 | O31: =O$45+P31 -> 7.06 | P31: 7 | T31: =T$45+U31 -> 7.06 | U31: 7 | V31: 501.2 | W31: 9.641 | Z31: =Z$45+AA31 -> 7.06 | AA31: 7 | AF31: 7 | AK31: 7 | AP31: 7
B32: =B$45+C32 -> 91.1 | C32: 6.5 | H32: =H$45+I32 -> 6.56 | I32: 6.5 | O32: =O$45+P32 -> 6.56 | P32: 6.5 | T32: =T$45+U32 -> 6.56 | U32: 6.5 | Z32: =Z$45+AA32 -> 6.56 | AA32: 6.5 | AF32: 6.5 | AK32: 6.5 | AP32: 6.5
B33: =B$45+C33 -> 90.6 | C33: 6 | D33: 465.6 | E33: 9.584 | H33: =H$45+I33 -> 6.06 | I33: 6 | J33: 256.6 | K33: =J33*Head!$K$12/1000 -> 0.017397908 | M33: 16.75 | O33: =O$45+P33 -> 6.06 | P33: 6 | Q33: 1029 | R33: 7.905 | T33: =T$45+U33 -> 6.06 | U33: 6 | V33: 628.9 | W33: 9.146 | Z33: =Z$45+AA33 -> 6.06 | AA33: 6 | AB33: 1720 | AC33: 8.638 | AF33: 6 | AK33: 6 | AP33: 6
B34: =B$45+C34 -> 90.1 | C34: 5.5 | H34: =H$45+I34 -> 5.56 | I34: 5.5 | O34: =O$45+P34 -> 5.56 | P34: 5.5 | T34: =T$45+U34 -> 5.56 | U34: 5.5 | Z34: =Z$45+AA34 -> 5.56 | AA34: 5.5 | AF34: 5.5 | AK34: 5.5 | AP34: 5.5
B35: =B$45+C35 -> 89.6 | C35: 5 | D35: 462.1 | E35: 10.82 | H35: =H$45+I35 -> 5.06 | I35: 5 | J35: 312.7 | K35: =J35*Head!$K$12/1000 -> 0.021201581 | M35: 14.16 | O35: =O$45+P35 -> 5.06 | P35: 5 | T35: =T$45+U35 -> 5.06 | U35: 5 | Z35: =Z$45+AA35 -> 5.06 | AA35: 5 | AF35: 5 | AK35: 5 | AP35: 5
B36: =B$45+C36 -> 89.1 | C36: 4.5 | H36: =H$45+I36 -> 4.56 | I36: 4.5 | O36: =O$45+P36 -> 4.56 | P36: 4.5 | T36: =T$45+U36 -> 4.56 | U36: 4.5 | Z36: =Z$45+AA36 -> 4.56 | AA36: 4.5 | AF36: 4.5 | AK36: 4.5 | AP36: 4.5
A37: G=90, souce at top | B37: =B$45+C37 -> 88.6 | C37: 4 | D37: 453.4 | E37: 9.257 | H37: =H$45+I37 -> 4.06 | I37: 4 | J37: 362 | K37: =J37*Head!$K$12/1000 -> 0.024544203 | M37: 13.04 | O37: =O$45+P37 -> 4.06 | P37: 4 | Q37: 1039 | R37: 8.103 | T37: =T$45+U37 -> 4.06 | U37: 4 | V37: 835.6 | W37: 8.434 | Z37: =Z$45+AA37 -> 4.06 | AA37: 4 | AB37: 1730 | AC37: 8.582 | AF37: 4 | AK37: 4 | AP37: 4
A38: couch moved in LONG | B38: =B$45+C38 -> 88.1 | C38: 3.5 | H38: =H$45+I38 -> 3.56 | I38: 3.5 | O38: =O$45+P38 -> 3.56 | P38: 3.5 | T38: =T$45+U38 -> 3.56 | U38: 3.5 | Z38: =Z$45+AA38 -> 3.56 | AA38: 3.5 | AF38: 3.5 | AK38: 3.5 | AP38: 3.5
A39: detector long axis on couch long axis | B39: =B$45+C39 -> 87.6 | C39: 3 | D39: 466 | E39: 9.564 | H39: =H$45+I39 -> 3.06 | I39: 3 | J39: 399.2 | K39: =J39*Head!$K$12/1000 -> 0.027066425 | M39: 11.71 | O39: =O$45+P39 -> 3.06 | P39: 3 | T39: =T$45+U39 -> 3.06 | U39: 3 | Z39: =Z$45+AA39 -> 3.06 | AA39: 3 | AF39: 3 | AK39: 3 | AP39: 3
B40: =B$45+C40 -> 87.1 | C40: 2.5 | H40: =H$45+I40 -> 2.56 | I40: 2.5 | O40: =O$45+P40 -> 2.56 | P40: 2.5 | T40: =T$45+U40 -> 2.56 | U40: 2.5 | Z40: =Z$45+AA40 -> 2.56 | AA40: 2.5 | AF40: 2.5 | AK40: 2.5 | AP40: 2.5
B41: =B$45+C41 -> 86.6 | C41: 2 | D41: 470 | E41: 8.52 | H41: =H$45+I41 -> 2.06 | I41: 2 | J41: 430 | K41: =J41*Head!$K$12/1000 -> 0.029154717 | M41: 11.61 | O41: =O$45+P41 -> 2.06 | P41: 2 | Q41: 1024 | R41: 8.044 | T41: =T$45+U41 -> 2.06 | U41: 2 | V41: 961.8 | W41: 8.049 | Z41: =Z$45+AA41 -> 2.06 | AA41: 2 | AB41: 1727 | AC41: 8.627 | AF41: 2 | AK41: 2 | AP41: 2
...

Sheet Sheet1
J9: Breast 360 | K9: Mode | L9: RF high
K10: kvp | L10: 125
K11: mA | L11: 10
K12: ms | L12: 10
K13: frames/s | L13: 7
K14: Fan type | L14: Full
K15: Arc type | L15: Half
